2025-09-05 00:19:32,524 ERROR: Failed to send email
Traceback (most recent call last):
  File "C:\Users\PRANS\Desktop\cnlab2\smtp_client.py", line 34, in send_mail
    smtp.login(SMTP_USER, SMTP_PASS)
  File "C:\Users\PRANS\AppData\Local\Programs\Python\Python312\Lib\smtplib.py", line 750, in login
    raise last_exception
  File "C:\Users\PRANS\AppData\Local\Programs\Python\Python312\Lib\smtplib.py", line 739, in login
    (code, resp) = self.auth(
                   ^^^^^^^^^^
  File "C:\Users\PRANS\AppData\Local\Programs\Python\Python312\Lib\smtplib.py", line 662, in auth
    raise SMTPAuthenticationError(code, resp)
smtplib.SMTPAuthenticationError: (535, b'5.7.8 Username and Password not accepted. For more information, go to\n5.7.8  https://support.google.com/mail/?p=BadCredentials d2e1a72fcca58-7722a26a0b3sm20172202b3a.10 - gsmtp')
2025-09-05 00:28:27,871 ERROR: Failed to send email
Traceback (most recent call last):
  File "C:\Users\PRANS\Desktop\cnlab2\smtp_client.py", line 34, in send_mail
    smtp.login(SMTP_USER, SMTP_PASS)
  File "C:\Users\PRANS\AppData\Local\Programs\Python\Python312\Lib\smtplib.py", line 750, in login
    raise last_exception
  File "C:\Users\PRANS\AppData\Local\Programs\Python\Python312\Lib\smtplib.py", line 739, in login
    (code, resp) = self.auth(
                   ^^^^^^^^^^
  File "C:\Users\PRANS\AppData\Local\Programs\Python\Python312\Lib\smtplib.py", line 662, in auth
    raise SMTPAuthenticationError(code, resp)
smtplib.SMTPAuthenticationError: (535, b'5.7.8 Username and Password not accepted. For more information, go to\n5.7.8  https://support.google.com/mail/?p=BadCredentials d9443c01a7336-24b2daec2dbsm70996735ad.124 - gsmtp')
2025-09-05 00:30:42,421 INFO: Email sent to ['yagyeshanshul@gmail.com'] via smtp.gmail.com:587
